<?xml version="1.0"?>
<robot name="yj_robot">

  <!-- 底板 -->
  <link name="base_link">
    <visual>
      <geometry>
        <cylinder radius="0.2" length="0.005" />
      </geometry>
      <material name="gray"/>
    </visual>
  </link>

  <!-- 左轮 -->
  <link name="left_wheel">
    <visual>
      <geometry>
        <cylinder radius="0.125" length="0.02" />
      </geometry>
      <material name="black"/>
    </visual>
  </link>

  <!-- 右轮 -->
  <link name="right_wheel">
    <visual>
      <geometry>
        <cylinder radius="0.125" length="0.02" />
      </geometry>
      <material name="black"/>
    </visual>
  </link>

  <!-- 从动轮 -->
  <link name="caster_wheel">
    <visual>
      <geometry>
        <cylinder radius="0.05" length="0.05" />
      </geometry>
      <material name="black"/>
    </visual>
  </link>

  <!-- 雷达 -->
  <link name="lidar">
    <visual>
      <geometry>
        <cylinder radius="0.2" length="0.1" />
      </geometry>
      <material name="blue"/>
    </visual>
  </link>

  <!-- IMU -->
  <link name="imu">
    <visual>
      <geometry>
        <sphere radius="0.05" />
      </geometry>
      <material name="red"/>
    </visual>
  </link>

  <!-- 关节：底板与轮子 -->
  <joint name="left_wheel_joint" type="revolute">
    <parent link="base_link"/>
    <child link="left_wheel"/>
    <axis xyz="0 0 1"/>
    <origin xyz="0.25 0 0.05"/>
    <limit effort="10" velocity="1.0"/>
  </joint>

  <joint name="right_wheel_joint" type="revolute">
    <parent link="base_link"/>
    <child link="right_wheel"/>
    <axis xyz="0 0 1"/>
    <origin xyz="-0.25 0 0.05"/>
    <limit effort="10" velocity="1.0"/>
  </joint>

  <!-- 关节：从动轮 -->
  <joint name="caster_wheel_joint" type="continuous">
    <parent link="base_link"/>
    <child link="caster_wheel"/>
    <axis xyz="0 0 1"/>
    <origin xyz="0 0.25 0.05"/>
  </joint>

  <!-- 关节：IMU -->
  <joint name="imu_joint" type="fixed">
    <parent link="base_link"/>
    <child link="imu"/>
    <origin xyz="0 0 0.1"/>
  </joint>

  <!-- 关节：雷达 -->
  <joint name="lidar_joint" type="fixed">
    <parent link="base_link"/>
    <child link="lidar"/>
    <origin xyz="0 0.2 0.1"/>
  </joint>

</robot>
